# 에러 처리

## 에러 처리의 필요성

에러가 발생하지 않는 코드를 작성하는 것은 불가능하다. 에러가 발생했을 때 에러에 대해서 적절히 대처해야 프로그램이 강제 종료되지 않는다.

직접적으로 에러를 발생하지는 않는 예외적인 상황도 있다.

```javascript
// button 요소가 없어도 Error를 던지지않고 null을 반환한다.
const $button = document.querySelector("button"); // null

// 에러 발생
$button.addEventListener("click", () => {
  console.log("클릭");
});

// 분기처리 하기
$button?.addEventListener("click", () => {
  console.log("클릭");
});
```

## try ... catch ... finally 문

분기처리 등을 통해서 예외 상황이나 에러를 처리할 수도 있지만 try catch 문을 이용하면 에러 발생시에 에러 처리 코드로 점프할 수 있다.

```javascript
try {
  // 실행할 코드
} catch (err) {
  // 에러 처리
} finally {
  // 반드시 실행되는코드
}
```

에러가 발생하도록 예상되는 곳에서 try catch 문을 이용한다면 프로그램이 강제 종료되지 않는다.

## Error 객체

Error 생성자 함수는 에러 객체를 생성한다. Error 생성자 함수에는 에러를 상세히 설명하는 에러 메시지를 인수로 전달할 수 있다.

```javascript
const error = new Error("invalid");
```

Error 생성자 함수가 생성한 에러 객체는 `message 프로퍼티와 stack 프로퍼티`를 갖는다. message 프로퍼티의 값은 Error 생성자 함수에 인수로 전달한 값이고, stack 프로퍼티의 값은 에러를 발생시킨 콜스택의 호출 정보이다.

에러 객체에는 총 7가지의 에러 객체가 있다.

| 생성자 함수    | 인스턴스                                                |
| -------------- | ------------------------------------------------------- |
| Error          | 일반 에러 객체                                          |
| SyntaxError    | 자바스크립트 문법에 어긋났을 때                         |
| ReferenceError | 참조할 수 없는 식별자를 참조했을 때                     |
| TypeError      | 변수나 데이터 타입이 유효하지 않을 때                   |
| RangeError     | 숫자값의 허용 범위를 벗어났을 때                        |
| URIError       | encodeURI, decodeURI 함수에 부적절한 인수를 전달했을 때 |
| EvalError      | eval 함수에 부적절한 인수를 전달했을 때                 |

```javascript
1 @ 1; // SyntaxError
foo(); // ReferenceError
null.foo; // TypeError
new Array(-1); // RangeError
decodeURIComponent("%"); // URIError
```

## throw 문

Error 생성자 함수로 에러 객체를 생성했다고 에러가 발생하는 것은 아니다. 즉 `에러 객체의 생성과 에러 발생은 명백히 다르다.`

```javascript
try {
  new Error("에러 발생");
} catch (error) {
  console.log(error, "?");
}
```

에러를 발생 시키려면 throw 문으로 에러 객체를 던져야 한다.

## 에러의 전파

에러는 호출자 방향으로 전파된다. 즉 콜 스택의 아래 방향으로 전파된다.

```javascript
const bottom = () => {
  throw Error("바닥부터");
};
const middle = () => {
  bottom();
};

const top1 = () => {
  middle();
};

try {
  top1();
} catch (error) {
  console.log(error);
}
```

<img width="350" alt="스크린샷 2024-04-25 오후 4 51 38" src="https://gist.github.com/assets/78193416/b748683a-e572-46cf-87fe-88ff48f60741">

중간에 위치한 middle, top1 함수에서 에러가 발생하면 bottom 함수로 전파된다. 위 이미지를 보면 stack 정보도 차례대로 잘 나와 있는 것을 확인할 수 있다.

주의할 점은 비동기 함수로 처리한 콜백 함수의 경우에는 실제 실행되는 시점에서는 실행 컨텍스트가 없어 에러를 throw해도 받아줄 catch 문이 없다는 점만 주의하자.
